Workbook

Sheet Instructions
A1: DERT #2040 - REBUILT Scouting Workbook
A2: Import data from the DERT Scout web app (index.html) by scanning its QR codes.
A5: ONE-TIME SETUP (each laptop)
A6: 1 | B6: Turn OFF Excel AutoComplete: File > Options > Advanced > uncheck 'Enable AutoComplete for cell values'.
B7: Otherwise Excel may 'finish' a scanned value for you (e.g. 'Depot' becomes 'Depot; Outpost') and the data will be wrong.
A8: 2 | B8: Use a USB/Bluetooth QR scanner in keyboard mode (most scanners default to this). Set its keyboard language to match Windows.
A9: 3 | B9: Test: open Notepad and scan a code - you should see values separated by tabs and the cursor should jump to a new line at the end.
A11: IMPORTING MATCHES
A12: 1 | B12: Go to the Scans sheet and click the first EMPTY cell in column A (Schema).
A13: 2 | B13: Scan the student's QR code. The whole match fills one row and the cursor moves to the next row automatically.
A14: 3 | B14: Repeat for every QR code. Keep scanning - the table grows by itself.
A15: 4 | B15: Made a mistake? Delete the whole row (right-click row number > Delete) and scan again.
A17: CHECKING THE DATA
A18: 1 | B18: Once TBA has the team list (a week or two before the event), paste it on the TBA Teams sheet. Once it has the match schedule
B19: (usually the day before quals), paste it on the TBA Schedule sheet. The steps are on those sheets.
A20: 2 | B20: Every few matches, open the Scouting Check sheet. Red numbers = something to fix; the list below them says what and in which Excel row.
A22: SHEETS
A23: - | B23: Scans - raw data, one row per robot per match. Do not change the column headers or their order.
A24: - | B24: Team Summary - averages per team (updates automatically). Pick list on the right is sorted by average total points.
A25: - | B25: Team Lookup - type a team number in the yellow cell to see every match and all observations for that team.
A26: - | B26: Scouting Check - duplicate scans, matches without 6 scans and, with the TBA schedule, unscouted robots, team-number typos and wrong alliances.
A27: - | B27: TBA Schedule - paste TBA's Flat Schedule here. Nothing else to type.
A28: - | B28: TBA Teams - paste TBA's Team List here: catches team numbers that aren't at the event, and Team Lookup shows the team's name.
A30: LEGEND
A31: - | B31: Teal header = column names (must match the web app). Yellow cell = type here. Everything else is calculated or scanned - don't edit.
A32: - | B32: Points: fuel in active Hub = 1 pt. Tower Level 1 = 15 pts in auto / 10 pts in teleop, Level 2 = 20, Level 3 = 30 (2026 REBUILT Game Manual, Table 6-4).
A33: - | B33: Ratings (Driver skill, Robot speed, Shooting accuracy) are 1 = poor to 5 = great. Multi-choice answers are separated by '; '.
A34: - | B34: Requires Microsoft 365 or Excel 2024 (uses FILTER, SORTBY, HSTACK, VSTACK, TEXTBEFORE). Excel 2021 and older show #NAME? errors.
A35: - | B35: Schema (column A) is filled in by every QR code (S39-44228b4d for this workbook). A RED row came from a different version
B36: of the scouting form, so its answers are in the wrong columns: delete it, update the app on that phone (open it on Wi-Fi), scan again.
A38: IF YOU CHANGE THE WEB FORM
A39: - | B39: Adding, removing or renaming fields in index.html changes the QR columns and the Schema stamp. Update the header list in
B40: build-excel.ps1 to match (the web app's QR screen has an 'Excel column headers' section you can copy) and rebuild this workbook,
B41: otherwise every new scan shows up red. Check the Team Summary formulas too.
A43: EXAMPLE ROW (what one scanned match looks like)
B44: Schema: S39-44228b4d
B45: Match type: Qual
B46: Match #: 12
B47: Team #: 2040
B48: Alliance: Blue
...

Sheet Scans
A1: Schema | B1: Match type | C1: Match # | D1: Team # | E1: Alliance | F1: Station | G1: Scout name | H1: Robot on field? | I1: Starting position | J1: Fuel preloaded | K1: Auto fuel scored | L1: Auto fuel missed | M1: Auto path | N1: Picked up fuel from | O1: Tower climb in auto | P1: Teleop fuel scored | Q1: Teleop fuel missed | R1: Intake from | S1: Shoots from | T1: Drives over / through | U1: Inactive Hub behavior | V1: Fuel it can carry | W1: Played defense | X1: Was defended | Y1: Tower climb | Z1: Climb time | AA1: Driver skill | AB1: Robot speed | AC1: Shooting accuracy | AD1: Problems | AE1: Minor fouls | AF1: Major fouls | AG1: Card | AH1: Pick? | AI1: Observations | AJ1: Auto pts | AK1: Teleop fuel pts | AL1: Climb pts | AM1: Total pts | AN1: Submitted
A2: S39-44228b4d | B2: Qual | C2: 1 | D2: 2039 | E2: Red | F2: 1 | G2: Ava | H2: Yes | I2: Right | J2: 8 | K2: 1 | L2: 1 | M2: Left start line | O2: None | P2: 1 | Q2: 1 | R2: Outpost / Human Player; Depot | S2: Close to Hub | U2: Plays defense | V2: 1–10 | W2: A lot | X2: No | Y2: None | AA2: 2 | AB2: 1 | AC2: 1 | AE2: 1 | AF2: 0 | AG2: None | AH2: Maybe | AI2: Struggled to score; aggressive defender | AJ2: 1 | AK2: 1 | AL2: 0 | AM2: 2 | AN2: 3/20/2026, 9:04:39 AM
A3: S39-44228b4d | B3: Qual | C3: 1 | D3: 6237 | E3: Red | F3: 2 | G3: Ben | H3: Yes | I3: Left | J3: 8 | K3: 2 | L3: 1 | M3: Left start line | O3: None | P3: 47 | Q3: 22 | R3: Neutral Zone floor; Alliance Zone floor; Depot | S3: Close to Hub; Mid range; Long range; While moving | T3: Bump; Trench | U3: Collects / stockpiles; Passes fuel to our zone | V3: 40+ | W3: None | X3: No | Y3: None | AA3: 5 | AB3: 4 | AC3: 2 | AE3: 0 | AF3: 0 | AG3: None | AH3: Yes | AI3: Shoots well from long range; fed fuel to partners during inactive shift | AJ3: 2 | AK3: 47 | AL3: 0 | AM3: 49 | AN3: 3/20/2026, 9:03:43 AM
A4: S39-44228b4d | B4: Qual | C4: 1 | D4: 4645 | E4: Red | F4: 3 | G4: Chloe | H4: Yes | I4: Center | J4: 8 | K4: 4 | L4: 1 | M4: Left start line | O4: None | P4: 11 | Q4: 3 | R4: Neutral Zone floor; Outpost / Human Player | S4: Close to Hub; Mid range | T4: Trench | U4: Collects / stockpiles | V4: 26–40 | W4: None | X4: No | Y4: None | AA4: 3 | AB4: 3 | AC4: 5 | AD4: Stuck on Bump | AE4: 0 | AF4: 0 | AG4: None | AH4: No | AJ4: 4 | AK4: 11 | AL4: 0 | AM4: 15 | AN4: 3/20/2026, 9:04:52 AM
A5: S39-44228b4d | B5: Qual | C5: 1 | D5: 2022 | E5: Blue | F5: 1 | G5: Dev | H5: Yes | I5: Right | J5: 8 | K5: 4 | L5: 1 | M5: Left start line | O5: None | P5: 16 | Q5: 4 | R5: Neutral Zone floor; Outpost / Human Player | S5: Close to Hub; Mid range | T5: Trench | U5: Collects / stockpiles | V5: 26–40 | W5: None | X5: No | Y5: None | AA5: 4 | AB5: 3 | AC5: 4 | AD5: Stuck on Bump | AE5: 0 | AF5: 0 | AG5: None | AH5: Maybe | AJ5: 4 | AK5: 16 | AL5: 0 | AM5: 20 | AN5: 3/20/2026, 9:04:06 AM
A6: S39-44228b4d | B6: Qual | C6: 1 | D6: 2040 | E6: Blue | F6: 2 | G6: Ella | H6: Yes | I6: Left | J6: 5 | K6: 26 | L6: 8 | M6: Left start line; Went to Neutral Zone; Used Trench | N6: Neutral Zone | O6: None | P6: 61 | Q6: 18 | R6: Neutral Zone floor; Alliance Zone floor; Depot | S6: Close to Hub; Mid range; Long range; While moving | T6: Bump; Trench | U6: Collects / stockpiles; Passes fuel to our zone | V6: 40+ | W6: None | X6: No | Y6: None | AA6: 5 | AB6: 5 | AC6: 3 | AE6: 0 | AF6: 0 | AG6: None | AH6: Yes | AI6: Consistent cycles; shoots well from long range | AJ6: 26 | AK6: 61 | AL6: 0 | AM6: 87 | AN6: 3/20/2026, 9:04:04 AM
A7: S39-44228b4d | B7: Qual | C7: 1 | D7: 9082 | E7: Blue | F7: 3 | G7: Finn | H7: Yes | I7: Right | J7: 8 | K7: 11 | L7: 0 | M7: Left start line; Went to Neutral Zone; Used Trench | N7: Neutral Zone | O7: None | P7: 60 | Q7: 2 | R7: Neutral Zone floor; Alliance Zone floor; Depot | S7: Close to Hub; Mid range; Long range; While moving | T7: Bump; Trench | U7: Collects / stockpiles; Passes fuel to our zone | V7: 26–40 | W7: None | X7: Some | Y7: None | AA7: 5 | AB7: 4 | AC7: 5 | AE7: 0 | AF7: 0 | AG7: None | AH7: Yes | AI7: Consistent cycles; fed fuel to partners during inactive shift | AJ7: 11 | AK7: 60 | AL7: 0 | AM7: 71 | AN7: 3/20/2026, 9:04:51 AM
A8: S39-44228b4d | B8: Qual | C8: 2 | D8: 3284 | E8: Red | F8: 1 | G8: Ava | H8: Yes | I8: Left | J8: 8 | K8: 3 | L8: 1 | M8: Left start line | O8: None | P8: 7 | Q8: 3 | R8: Outpost / Human Player; Depot | S8: Close to Hub | U8: Plays defense | V8: 1–10 | W8: A lot | X8: No | Y8: None | AA8: 1 | AB8: 3 | AC8: 2 | AE8: 0 | AF8: 0 | AG8: None | AH8: Maybe | AI8: Struggled to score; aggressive defender | AJ8: 3 | AK8: 7 | AL8: 0 | AM8: 10 | AN8: 3/20/2026, 9:13:08 AM
A9: S39-44228b4d | B9: Qual | C9: 2 | D9: 1756 | E9: Red | F9: 2 | G9: Ben | H9: Yes | I9: Right | J9: 8 | K9: 5 | L9: 1 | M9: Left start line; Went to Neutral Zone; Crossed Bump | O9: None | P9: 66 | Q9: 15 | R9: Neutral Zone floor; Alliance Zone floor; Depot | S9: Close to Hub; Mid range; Long range; While moving | T9: Bump; Trench | U9: Collects / stockpiles; Passes fuel to our zone | V9: 40+ | W9: None | X9: No | Y9: None | AA9: 5 | AB9: 5 | AC9: 3 | AE9: 0 | AF9: 1 | AG9: None | AH9: Yes | AI9: Consistent cycles | AJ9: 5 | AK9: 66 | AL9: 0 | AM9: 71 | AN9: 3/20/2026, 9:13:18 AM
A10: S39-44228b4d | B10: Qual | C10: 2 | D10: 4655 | E10: Red | F10: 3 | G10: Chloe | H10: Yes | I10: Right | J10: 8 | K10: 3 | L10: 1 | M10: Left start line | O10: None | P10: 19 | Q10: 7 | R10: Neutral Zone floor; Alliance Zone floor; Depot | S10: Close to Hub; Mid range | T10: Bump; Trench | U10: Collects / stockpiles; Passes fuel to our zone | V10: 26–40 | W10: None | X10: Some | Y10: None | AA10: 3 | AB10: 4 | AC10: 3 | AE10: 0 | AF10: 1 | AG10: None | AH10: Maybe | AJ10: 3 | AK10: 19 | AL10: 0 | AM10: 22 | AN10: 3/20/2026, 9:11:57 AM
A11: S39-44228b4d | B11: Qual | C11: 2 | D11: 3067 | E11: Blue | F11: 1 | G11: Dev | H11: Yes | I11: Center | J11: 8 | K11: 2 | L11: 0 | M11: Left start line | O11: None | P11: 83 | Q11: 15 | R11: Neutral Zone floor; Alliance Zone floor; Depot | S11: Close to Hub; Mid range | T11: Bump | U11: Collects / stockpiles | V11: 26–40 | W11: None | X11: No | Y11: None | AA11: 4 | AB11: 3 | AC11: 5 | AE11: 0 | AF11: 0 | AG11: None | AH11: Maybe | AI11: Consistent cycles | AJ11: 2 | AK11: 83 | AL11: 0 | AM11: 85 | AN11: 3/20/2026, 9:12:06 AM
A12: S39-44228b4d | B12: Qual | C12: 2 | D12: 4143 | E12: Blue | F12: 2 | G12: Ella | H12: Yes | I12: Center | J12: 7 | K12: 32 | L12: 3 | M12: Left start line; Went to Neutral Zone; Used Trench | N12: Depot | O12: None | P12: 38 | Q12: 3 | R12: Neutral Zone floor; Alliance Zone floor; Depot | S12: Close to Hub; Mid range; Long range; While moving | T12: Bump; Trench | U12: Collects / stockpiles; Passes fuel to our zone | V12: 40+ | W12: None | X12: Heavily | Y12: None | AA12: 5 | AB12: 3 | AC12: 5 | AD12: Died / disabled | AE12: 0 | AF12: 0 | AG12: None | AH12: Yes | AI12: Robot stopped moving mid-match | AJ12: 32 | AK12: 38 | AL12: 0 | AM12: 70 | AN12: 3/20/2026, 9:13:18 AM
A13: S39-44228b4d | B13: Qual | C13: 2 | D13: 7848 | E13: Blue | F13: 3 | G13: Finn | H13: Yes | I13: Left | J13: 8 | K13: 2 | L13: 1 | M13: Left start line | O13: None | P13: 71 | Q13: 21 | R13: Neutral Zone floor; Alliance Zone floor; Depot | S13: Close to Hub; Mid range | T13: Trench | U13: Collects / stockpiles | V13: 26–40 | W13: None | X13: No | Y13: None | AA13: 3 | AB13: 2 | AC13: 4 | AE13: 0 | AF13: 0 | AG13: None | AH13: No | AI13: Consistent cycles | AJ13: 2 | AK13: 71 | AL13: 0 | AM13: 73 | AN13: 3/20/2026, 9:12:10 AM
A14: S39-44228b4d | B14: Qual | C14: 3 | D14: 7417 | E14: Red | F14: 1 | G14: Ava | H14: Yes | I14: Left | J14: 8 | K14: 4 | L14: 3 | M14: Left start line | O14: None | P14: 3 | Q14: 2 | R14: Outpost / Human Player; Depot | S14: Close to Hub | U14: Plays defense | V14: 1–10 | W14: None | X14: No | Y14: None | AA14: 1 | AB14: 1 | AC14: 1 | AE14: 0 | AF14: 1 | AG14: None | AH14: No | AI14: Struggled to score | AJ14: 4 | AK14: 3 | AL14: 0 | AM14: 7 | AN14: 3/20/2026, 9:20:35 AM
A15: S39-44228b4d | B15: Qual | C15: 3 | D15: 4787 | E15: Red | F15: 2 | G15: Ben | H15: Yes | I15: Center | J15: 7 | K15: 1 | L15: 1 | M15: Left start line | O15: None | P15: 10 | Q15: 6 | R15: Neutral Zone floor; Outpost / Human Player | S15: Close to Hub; Mid range | T15: Trench | U15: Collects / stockpiles | V15: 11–25 | W15: None | X15: No | Y15: None | AA15: 3 | AB15: 3 | AC15: 2 | AE15: 0 | AF15: 1 | AG15: None | AH15: Maybe | AJ15: 1 | AK15: 10 | AL15: 0 | AM15: 11 | AN15: 3/20/2026, 9:21:02 AM
A16: S39-44228b4d | B16: Qual | C16: 3 | D16: 4213 | E16: Red | F16: 3 | G16: Chloe | H16: Yes | I16: Center | J16: 8 | K16: 6 | L16: 2 | M16: Left start line | O16: None | P16: 27 | Q16: 9 | R16: Neutral Zone floor; Alliance Zone floor; Depot | S16: Close to Hub; Mid range | T16: Bump | U16: Collects / stockpiles | V16: 26–40 | W16: None | X16: No | Y16: None | AA16: 3 | AB16: 4 | AC16: 3 | AE16: 0 | AF16: 0 | AG16: None | AH16: Maybe | AJ16: 6 | AK16: 27 | AL16: 0 | AM16: 33 | AN16: 3/20/2026, 9:20:29 AM
A17: S39-44228b4d | B17: Qual | C17: 3 | D17: 1736 | E17: Blue | F17: 1 | G17: Dev | H17: Yes | I17: Left | J17: 5 | K17: 3 | L17: 2 | M17: Left start line | O17: None | P17: 24 | Q17: 16 | R17: Neutral Zone floor; Outpost / Human Player | S17: Close to Hub | T17: Trench | U17: Collects / stockpiles | V17: 11–25 | W17: None | X17: No | Y17: None | AA17: 3 | AB17: 1 | AC17: 4 | AE17: 2 | AF17: 0 | AG17: None | AH17: Maybe | AJ17: 3 | AK17: 24 | AL17: 0 | AM17: 27 | AN17: 3/20/2026, 9:20:00 AM
A18: S39-44228b4d | B18: Qual | C18: 3 | D18: 5442 | E18: Blue | F18: 2 | G18: Ella | H18: Yes | I18: Center | J18: 8 | K18: 0 | L18: 0 | O18: None | P18: 20 | Q18: 10 | R18: Neutral Zone floor; Outpost / Human Player | S18: Close to Hub; Mid range | T18: Trench | U18: Collects / stockpiles | V18: 11–25 | W18: None | X18: No | Y18: None | AA18: 3 | AB18: 3 | AC18: 3 | AE18: 2 | AF18: 0 | AG18: None | AH18: Maybe | AJ18: 0 | AK18: 20 | AL18: 0 | AM18: 20 | AN18: 3/20/2026, 9:21:02 AM
A19: S39-44228b4d | B19: Qual | C19: 3 | D19: 8719 | E19: Blue | F19: 3 | G19: Finn | H19: Yes | I19: Right | J19: 5 | K19: 5 | L19: 3 | M19: Left start line | O19: None | P19: 2 | Q19: 1 | R19: Outpost / Human Player; Depot | S19: Close to Hub | U19: Idle | V19: 1–10 | W19: Some | X19: No | Y19: None | AA19: 2 | AB19: 3 | AC19: 1 | AE19: 0 | AF19: 0 | AG19: None | AH19: No | AI19: Struggled to score | AJ19: 5 | AK19: 2 | AL19: 0 | AM19: 7 | AN19: 3/20/2026, 9:21:06 AM
A20: S39-44228b4d | B20: Qual | C20: 4 | D20: 1625 | E20: Red | F20: 1 | G20: Ava | H20: Yes | I20: Center | J20: 8 | K20: 28 | L20: 7 | M20: Left start line; Went to Neutral Zone; Crossed Bump | N20: Depot | O20: None | P20: 74 | Q20: 18 | R20: Neutral Zone floor; Alliance Zone floor; Depot | S20: Close to Hub; Mid range; Long range; While moving | T20: Bump; Trench | U20: Collects / stockpiles; Passes fuel to our zone | V20: 40+ | W20: None | X20: No | Y20: None | AA20: 5 | AB20: 5 | AC20: 3 | AE20: 0 | AF20: 0 | AG20: None | AH20: Yes | AI20: Consistent cycles; fed fuel to partners during inactive shift | AJ20: 28 | AK20: 74 | AL20: 0 | AM20: 102 | AN20: 3/20/2026, 9:28:54 AM
A21: S39-44228b4d | B21: Qual | C21: 4 | D21: 3488 | E21: Red | F21: 2 | G21: Ben | H21: Yes | I21: Left | J21: 8 | K21: 1 | L21: 1 | M21: Left start line | O21: None | P21: 25 | Q21: 16 | R21: Neutral Zone floor; Outpost / Human Player | S21: Close to Hub | T21: Bump | U21: Collects / stockpiles | V21: 11–25 | W21: None | X21: No | Y21: None | AA21: 2 | AB21: 3 | AC21: 3 | AE21: 0 | AF21: 0 | AG21: None | AH21: No | AJ21: 1 | AK21: 25 | AL21: 0 | AM21: 26 | AN21: 3/20/2026, 9:29:11 AM
A22: S39-44228b4d | B22: Qual | C22: 4 | D22: 4423 | E22: Red | F22: 3 | G22: Chloe | H22: Yes | I22: Left | J22: 8 | K22: 1 | L22: 0 | M22: Left start line | O22: None | P22: 40 | Q22: 10 | R22: Neutral Zone floor; Alliance Zone floor; Depot | S22: Close to Hub; Mid range | T22: Bump; Trench | U22: Collects / stockpiles; Passes fuel to our zone | V22: 26–40 | W22: None | X22: Heavily | Y22: Level 1 | Z22: 5–10 s | AA22: 4 | AB22: 3 | AC22: 4 | AE22: 0 | AF22: 0 | AG22: None | AH22: Yes | AI22: Climbed L1 cleanly | AJ22: 1 | AK22: 40 | AL22: 10 | AM22: 51 | AN22: 3/20/2026, 9:29:08 AM
A23: S39-44228b4d | B23: Qual | C23: 4 | D23: 8020 | E23: Blue | F23: 1 | G23: Dev | H23: Yes | I23: Right | J23: 8 | K23: 14 | L23: 2 | M23: Left start line; Went to Neutral Zone; Used Trench | N23: Depot | O23: None | P23: 65 | Q23: 10 | R23: Neutral Zone floor; Alliance Zone floor; Depot | S23: Close to Hub; Mid range; Long range; While moving | T23: Bump; Trench | U23: Collects / stockpiles; Passes fuel to our zone | V23: 40+ | W23: None | X23: No | Y23: None | AA23: 4 | AB23: 5 | AC23: 4 | AE23: 0 | AF23: 0 | AG23: None | AH23: Yes | AI23: Consistent cycles | AJ23: 14 | AK23: 65 | AL23: 0 | AM23: 79 | AN23: 3/20/2026, 9:29:17 AM
A24: S39-44228b4d | B24: Qual | C24: 4 | D24: 2861 | E24: Blue | F24: 2 | G24: Ella | H24: Yes | I24: Left | J24: 8 | K24: 6 | L24: 0 | M24: Left start line | O24: None | P24: 67 | Q24: 2 | R24: Neutral Zone floor; Alliance Zone floor; Depot | S24: Close to Hub; Mid range; Long range; While moving | T24: Bump; Trench | U24: Collects / stockpiles; Passes fuel to our zone | V24: 40+ | W24: None | X24: Heavily | Y24: None | AA24: 5 | AB24: 4 | AC24: 5 | AE24: 0 | AF24: 0 | AG24: None | AH24: Yes | AI24: Consistent cycles | AJ24: 6 | AK24: 67 | AL24: 0 | AM24: 73 | AN24: 3/20/2026, 9:29:18 AM
A25: S39-44228b4d | B25: Qual | C25: 4 | D25: 648 | E25: Blue | F25: 3 | G25: Finn | H25: Yes | I25: Right | J25: 8 | K25: 4 | L25: 2 | M25: Left start line | O25: None | P25: 14 | Q25: 7 | R25: Neutral Zone floor; Outpost / Human Player | S25: Close to Hub | U25: Idle | V25: 11–25 | W25: A lot | X25: No | Y25: None | AA25: 1 | AB25: 2 | AC25: 3 | AE25: 0 | AF25: 0 | AG25: None | AH25: No | AI25: Aggressive defender | AJ25: 4 | AK25: 14 | AL25: 0 | AM25: 18 | AN25: 3/20/2026, 9:28:15 AM
A26: S39-44228b4d | B26: Qual | C26: 5 | D26: 8029 | E26: Red | F26: 1 | G26: Ava | H26: Yes | I26: Right | J26: 5 | K26: 6 | L26: 4 | M26: Left start line; Went to Neutral Zone; Crossed Bump | N26: Neutral Zone | O26: None | P26: 3 | Q26: 2 | R26: Outpost / Human Player; Depot | S26: Close to Hub | U26: Shoots anyway | V26: 1–10 | W26: Some | X26: No | Y26: None | AA26: 1 | AB26: 3 | AC26: 3 | AE26: 0 | AF26: 0 | AG26: None | AH26: Maybe | AI26: Struggled to score | AJ26: 6 | AK26: 3 | AL26: 0 | AM26: 9 | AN26: 3/20/2026, 9:36:08 AM
A27: S39-44228b4d | B27: Qual | C27: 5 | D27: 4096 | E27: Red | F27: 2 | G27: Ben | H27: Yes | I27: Right | J27: 8 | K27: 7 | L27: 1 | M27: Left start line | O27: None | P27: 86 | Q27: 11 | R27: Neutral Zone floor; Alliance Zone floor; Depot | S27: Close to Hub; Mid range | T27: Bump; Trench | U27: Collects / stockpiles; Passes fuel to our zone | V27: 26–40 | W27: None | X27: No | Y27: None | AA27: 5 | AB27: 4 | AC27: 4 | AE27: 0 | AF27: 0 | AG27: None | AH27: Maybe | AI27: Consistent cycles | AJ27: 7 | AK27: 86 | AL27: 0 | AM27: 93 | AN27: 3/20/2026, 9:37:07 AM
A28: S39-44228b4d | B28: Qual | C28: 5 | D28: 4156 | E28: Red | F28: 3 | G28: Chloe | H28: Yes | I28: Right | J28: 8 | K28: 1 | L28: 0 | M28: Left start line | O28: None | P28: 2 | Q28: 1 | R28: Outpost / Human Player; Depot | S28: Close to Hub | U28: Plays defense | V28: 1–10 | W28: None | X28: No | Y28: None | AA28: 1 | AB28: 2 | AC28: 4 | AE28: 0 | AF28: 0 | AG28: None | AH28: No | AI28: Struggled to score | AJ28: 1 | AK28: 2 | AL28: 0 | AM28: 3 | AN28: 3/20/2026, 9:36:21 AM
A29: S39-44228b4d | B29: Qual | C29: 5 | D29: 8096 | E29: Blue | F29: 1 | G29: Dev | H29: Yes | I29: Left | J29: 8 | K29: 17 | L29: 6 | M29: Left start line; Went to Neutral Zone; Used Trench | N29: Neutral Zone | O29: None | P29: 7 | Q29: 3 | R29: Neutral Zone floor; Outpost / Human Player | S29: Close to Hub; Mid range | T29: Trench | U29: Collects / stockpiles | V29: 11–25 | W29: None | X29: No | Y29: None | AA29: 2 | AB29: 4 | AC29: 3 | AE29: 0 | AF29: 1 | AG29: None | AH29: Maybe | AI29: Struggled to score | AJ29: 17 | AK29: 7 | AL29: 0 | AM29: 24 | AN29: 3/20/2026, 9:36:11 AM
A30: S39-44228b4d | B30: Qual | C30: 5 | D30: 7472 | E30: Blue | F30: 2 | G30: Ella | H30: Yes | I30: Right | J30: 8 | K30: 8 | L30: 7 | M30: Left start line | O30: None | P30: 0 | Q30: 0 | R30: Outpost / Human Player; Depot | S30: Close to Hub | U30: Shoots anyway | V30: 1–10 | W30: None | X30: No | Y30: None | AA30: 2 | AB30: 1 | AC30: 3 | AE30: 0 | AF30: 0 | AG30: None | AH30: No | AI30: Struggled to score | AJ30: 8 | AK30: 0 | AL30: 0 | AM30: 8 | AN30: 3/20/2026, 9:35:54 AM
A31: S39-44228b4d | B31: Qual | C31: 5 | D31: 2481 | E31: Blue | F31: 3 | G31: Finn | H31: Yes | I31: Right | J31: 8 | K31: 80 | L31: 22 | M31: Left start line; Went to Neutral Zone; Crossed Bump | N31: Depot | O31: None | P31: 38 | Q31: 10 | R31: Neutral Zone floor; Alliance Zone floor; Depot | S31: Close to Hub; Mid range; Long range; While moving | T31: Bump; Trench | U31: Collects / stockpiles; Passes fuel to our zone | V31: 40+ | W31: None | X31: Some | Y31: None | AA31: 4 | AB31: 5 | AC31: 2 | AE31: 1 | AF31: 0 | AG31: None | AH31: Yes | AI31: Shoots well from long range; fed fuel to partners during inactive shift | AJ31: 80 | AK31: 38 | AL31: 0 | AM31: 118 | AN31: 3/20/2026, 9:36:14 AM
A32: S39-44228b4d | B32: Qual | C32: 6 | D32: 3284 | E32: Red | F32: 1 | G32: Ava | H32: Yes | I32: Left | J32: 8 | K32: 10 | L32: 4 | M32: Left start line; Went to Neutral Zone; Used Trench | N32: Depot | O32: None | P32: 11 | Q32: 5 | R32: Outpost / Human Player; Depot | S32: Close to Hub | U32: Plays defense | V32: 1–10 | W32: A lot | X32: No | Y32: None | AA32: 2 | AB32: 1 | AC32: 3 | AE32: 2 | AF32: 0 | AG32: None | AH32: No | AI32: Aggressive defender | AJ32: 10 | AK32: 11 | AL32: 0 | AM32: 21 | AN32: 3/20/2026, 9:44:44 AM
A33: S39-44228b4d | B33: Qual | C33: 6 | D33: 5442 | E33: Red | F33: 2 | G33: Ben | H33: Yes | I33: Center | J33: 8 | K33: 1 | L33: 0 | M33: Left start line | O33: None | P33: 17 | Q33: 7 | R33: Neutral Zone floor; Outpost / Human Player | S33: Close to Hub; Mid range | T33: Trench | U33: Collects / stockpiles | V33: 11–25 | W33: None | X33: No | Y33: None | AA33: 2 | AB33: 3 | AC33: 4 | AE33: 1 | AF33: 0 | AG33: None | AH33: Yes | AJ33: 1 | AK33: 17 | AL33: 0 | AM33: 18 | AN33: 3/20/2026, 9:43:29 AM
A34: S39-44228b4d | B34: Qual | C34: 6 | D34: 6651 | E34: Red | F34: 3 | G34: Chloe | H34: Yes | I34: Left | J34: 8 | K34: 9 | L34: 3 | M34: Left start line; Went to Neutral Zone; Crossed Bump | N34: Neutral Zone | O34: None | P34: 14 | Q34: 5 | R34: Neutral Zone floor; Outpost / Human Player | S34: Close to Hub | U34: Collects / stockpiles | V34: 11–25 | W34: None | X34: No | Y34: None | AA34: 2 | AB34: 1 | AC34: 5 | AE34: 0 | AF34: 0 | AG34: None | AH34: No | AJ34: 9 | AK34: 14 | AL34: 0 | AM34: 23 | AN34: 3/20/2026, 9:43:38 AM
A35: S39-44228b4d | B35: Qual | C35: 6 | D35: 2039 | E35: Blue | F35: 1 | G35: Dev | H35: Yes | I35: Right | J35: 8 | K35: 2 | L35: 2 | M35: Left start line | O35: None | P35: 3 | Q35: 3 | R35: Outpost / Human Player; Depot | S35: Close to Hub | U35: Plays defense | V35: 1–10 | W35: A lot | X35: No | Y35: Level 1 | Z35: 5–10 s | AA35: 1 | AB35: 1 | AC35: 2 | AE35: 0 | AF35: 0 | AG35: None | AH35: No | AI35: Struggled to score; climbed L1 cleanly; aggressive defender | AJ35: 2 | AK35: 3 | AL35: 10 | AM35: 15 | AN35: 3/20/2026, 9:44:24 AM
A36: S39-44228b4d | B36: Qual | C36: 6 | D36: 4655 | E36: Blue | F36: 2 | G36: Ella | H36: Yes | I36: Right | J36: 8 | K36: 9 | L36: 3 | M36: Left start line; Went to Neutral Zone; Crossed Bump | N36: Depot | O36: None | P36: 32 | Q36: 12 | R36: Neutral Zone floor; Alliance Zone floor; Depot | S36: Close to Hub; Mid range | T36: Bump; Trench | U36: Collects / stockpiles; Passes fuel to our zone | V36: 26–40 | W36: Some | X36: No | Y36: None | AA36: 4 | AB36: 3 | AC36: 5 | AE36: 0 | AF36: 0 | AG36: None | AH36: No | AI36: Fed fuel to partners during inactive shift | AJ36: 9 | AK36: 32 | AL36: 0 | AM36: 41 | AN36: 3/20/2026, 9:44:41 AM
A37: S39-44228b4d | B37: Qual | C37: 6 | D37: 4213 | E37: Blue | F37: 3 | G37: Finn | H37: Yes | I37: Center | J37: 8 | K37: 7 | L37: 3 | M37: Left start line | O37: None | P37: 24 | Q37: 10 | R37: Neutral Zone floor; Alliance Zone floor; Depot | S37: Close to Hub; Mid range | T37: Bump | U37: Collects / stockpiles | V37: 26–40 | W37: None | X37: No | Y37: None | AA37: 3 | AB37: 4 | AC37: 3 | AE37: 0 | AF37: 0 | AG37: None | AH37: Yes | AJ37: 7 | AK37: 24 | AL37: 0 | AM37: 31 | AN37: 3/20/2026, 9:43:33 AM
A38: S39-44228b4d | B38: Qual | C38: 7 | D38: 2040 | E38: Red | F38: 1 | G38: Ava | H38: Yes | I38: Left | J38: 5 | K38: 18 | L38: 4 | M38: Left start line; Went to Neutral Zone; Used Trench | N38: Neutral Zone | O38: None | P38: 127 | Q38: 25 | R38: Neutral Zone floor; Alliance Zone floor; Depot | S38: Close to Hub; Mid range; Long range; While moving | T38: Bump; Trench | U38: Collects / stockpiles; Passes fuel to our zone | V38: 40+ | W38: None | X38: No | Y38: None | AA38: 4 | AB38: 5 | AC38: 5 | AE38: 0 | AF38: 0 | AG38: None | AH38: Yes | AI38: High-volume scorer; shoots well from long range | AJ38: 18 | AK38: 127 | AL38: 0 | AM38: 145 | AN38: 3/20/2026, 9:51:28 AM
A39: S39-44228b4d | B39: Qual | C39: 7 | D39: 4143 | E39: Red | F39: 2 | G39: Ben | H39: Yes | I39: Center | J39: 7 | K39: 55 | L39: 8 | M39: Left start line; Went to Neutral Zone; Crossed Bump | N39: Neutral Zone | O39: None | P39: 102 | Q39: 15 | R39: Neutral Zone floor; Alliance Zone floor; Depot | S39: Close to Hub; Mid range; Long range; While moving | T39: Bump; Trench | U39: Collects / stockpiles; Passes fuel to our zone | V39: 40+ | W39: None | X39: Heavily | Y39: None | AA39: 5 | AB39: 5 | AC39: 5 | AE39: 0 | AF39: 0 | AG39: None | AH39: Yes | AI39: High-volume scorer; fed fuel to partners during inactive shift | AJ39: 55 | AK39: 102 | AL39: 0 | AM39: 157 | AN39: 3/20/2026, 9:51:23 AM
A40: S39-44228b4d | B40: Qual | C40: 7 | D40: 4645 | E40: Red | F40: 3 | G40: Chloe | H40: Yes | I40: Center | J40: 8 | K40: 3 | L40: 1 | M40: Left start line | O40: None | P40: 50 | Q40: 12 | R40: Neutral Zone floor; Outpost / Human Player | S40: Close to Hub; Mid range | T40: Trench | U40: Collects / stockpiles | V40: 26–40 | W40: None | X40: No | Y40: None | AA40: 2 | AB40: 3 | AC40: 4 | AE40: 0 | AF40: 0 | AG40: None | AH40: Maybe | AI40: Consistent cycles | AJ40: 3 | AK40: 50 | AL40: 0 | AM40: 53 | AN40: 3/20/2026, 9:52:13 AM
...

Sheet Team Summary
A1: DERT #2040 - REBUILT Team Summary
A2: Updates automatically from the Scans sheet. One row per team, sorted by team number. Rank 1 = highest average total points.
T3: PICK LIST - sorted by average total points
A4: Team # | B4: Matches | C4: Avg auto pts | D4: Avg teleop fuel | E4: Avg climb pts | F4: Avg total pts | G4: Best total | H4: Shot accuracy | I4: Auto climb rate | J4: Endgame climb rate | K4: Level 3 climbs | L4: Avg driver skill | M4: Defense matches | N4: Matches w/ problems | O4: Total fouls | P4: Pick: Yes votes | Q4: No-shows | R4: Rank | T4: Rank | U4: Team # | V4: Avg total pts | W4: Avg auto pts | X4: Avg teleop fuel | Y4: Avg climb pts | Z4: Endgame climb rate | AA4: Shot accuracy | AB4: Matches w/ problems | AC4: Pick: Yes votes
A5: {=IFERROR(_xlfn._xlws.SORT(_xlfn.UNIQUE(_xlfn._xlws.FILTER(Scans[Team '#],Scans[Team '#]<>""))),"")} -> 648 | B5: {=IF(_xlfn.ANCHORARRAY(A5)="","",COUNTIFS(Scans[Team '#],_xlfn.ANCHORARRAY(A5)))} -> 12 | C5: {=IF(_xlfn.ANCHORARRAY(A5)="","",AVERAGEIFS(Scans[Auto pts],Scans[Team '#],_xlfn.ANCHORARRAY(A5)))} -> 8.1666667 | D5: {=IF(_xlfn.ANCHORARRAY(A5)="","",AVERAGEIFS(Scans[Teleop fuel pts],Scans[Team '#],_xlfn.ANCHORARRAY(A5)))} -> 14 | E5: {=IF(_xlfn.ANCHORARRAY(A5)="","",AVERAGEIFS(Scans[Climb pts],Scans[Team '#],_xlfn.ANCHORARRAY(A5)))} -> 0 | F5: {=IF(_xlfn.ANCHORARRAY(A5)="","",AVERAGEIFS(Scans[Total pts],Scans[Team '#],_xlfn.ANCHORARRAY(A5)))} -> 22.166667 | G5: {=IF(_xlfn.ANCHORARRAY(A5)="","",_xlfn.MAXIFS(Scans[Total pts],Scans[Team '#],_xlfn.ANCHORARRAY(A5)))} -> 37 | H5: {=IF(_xlfn.ANCHORARRAY(A5)="","",IFERROR((SUMIFS(Scans[Auto fuel scored],Scans[Team '#],_xlfn.ANCHORARRAY(A5))+SUMIFS(Scans[Teleop fuel scored],Scans[Team '#],_xlfn.ANCHORARRAY(A5)))/(SUMIFS(Scans[Auto fuel scored],Scans[Team '#],_xlfn.ANCHORARRAY(A5))+SUMIFS(Scans[Teleop fuel scored],Scans[Team '#],_xlfn.ANCHORARRAY(A5))+SUMIFS(Scans[Auto fuel missed],Scans[Team '#],_xlfn.ANCHORARRAY(A5))+SUMIFS(Scans[Teleop fuel missed],Scans[Team '#],_xlfn.ANCHORARRAY(A5))),""))} -> 0.67341772 | I5: {=IF(_xlfn.ANCHORARRAY(A5)="","",COUNTIFS(Scans[Team '#],_xlfn.ANCHORARRAY(A5),Scans[Tower climb in auto],"Level 1")/_xlfn.ANCHORARRAY(B5))} -> 0 | J5: {=IF(_xlfn.ANCHORARRAY(A5)="","",COUNTIFS(Scans[Team '#],_xlfn.ANCHORARRAY(A5),Scans[Tower climb],"Level*")/_xlfn.ANCHORARRAY(B5))} -> 0 | K5: {=IF(_xlfn.ANCHORARRAY(A5)="","",COUNTIFS(Scans[Team '#],_xlfn.ANCHORARRAY(A5),Scans[Tower climb],"Level 3"))} -> 0 | L5: {=IF(_xlfn.ANCHORARRAY(A5)="","",IFERROR(AVERAGEIFS(Scans[Driver skill],Scans[Team '#],_xlfn.ANCHORARRAY(A5)),""))} -> 2 | M5: {=IF(_xlfn.ANCHORARRAY(A5)="","",COUNTIFS(Scans[Team '#],_xlfn.ANCHORARRAY(A5),Scans[Played defense],"Some")+COUNTIFS(Scans[Team '#],_xlfn.ANCHORARRAY(A5),Scans[Played defense],"A lot"))} -> 12 | N5: {=IF(_xlfn.ANCHORARRAY(A5)="","",COUNTIFS(Scans[Team '#],_xlfn.ANCHORARRAY(A5),Scans[Problems],"<>"))} -> 2 | O5: {=IF(_xlfn.ANCHORARRAY(A5)="","",SUMIFS(Scans[Minor fouls],Scans[Team '#],_xlfn.ANCHORARRAY(A5))+SUMIFS(Scans[Major fouls],Scans[Team '#],_xlfn.ANCHORARRAY(A5)))} -> 1 | P5: {=IF(_xlfn.ANCHORARRAY(A5)="","",COUNTIFS(Scans[Team '#],_xlfn.ANCHORARRAY(A5),Scans[Pick?],"Yes"))} -> 0 | Q5: {=IF(_xlfn.ANCHORARRAY(A5)="","",COUNTIFS(Scans[Team '#],_xlfn.ANCHORARRAY(A5),Scans[Robot on field?],"No show"))} -> 0 | R5: {=IF(_xlfn.ANCHORARRAY(A5)="","",_xlfn.RANK.EQ(_xlfn.ANCHORARRAY(F5),_xlfn.ANCHORARRAY(F5)))} -> 25 | T5: {=IF(A5="","",_xlfn.SEQUENCE(ROWS(_xlfn.ANCHORARRAY(A5))))} -> 1 | U5: {=IF(A5="","",_xlfn.SORTBY(_xlfn.HSTACK(_xlfn.ANCHORARRAY(A5),_xlfn.ANCHORARRAY(F5),_xlfn.ANCHORARRAY(C5),_xlfn.ANCHORARRAY(D5),_xlfn.ANCHORARRAY(E5),_xlfn.ANCHORARRAY(J5),_xlfn.ANCHORARRAY(H5),_xlfn.ANCHORARRAY(N5),_xlfn.ANCHORARRAY(P5)),_xlfn.ANCHORARRAY(F5),-1))} -> 2481 | V5: 275.91667 | W5: 75.416667 | X5: 200.5 | Y5: 0 | Z5: 0 | AA5: 0.79572218 | AB5: 1 | AC5: 12
A6: 1625 | B6: 12 | C6: 26.416667 | D6: 70.583333 | E6: 0 | F6: 97 | G6: 137 | H6: 0.76679842 | I6: 0 | J6: 0 | K6: 0 | L6: 4.0833333 | M6: 1 | N6: 1 | O6: 3 | P6: 12 | Q6: 0 | R6: 5 | T6: 2 | U6: 4143 | V6: 166.75 | W6: 35.666667 | X6: 131.08333 | Y6: 0 | Z6: 0 | AA6: 0.87341772 | AB6: 3 | AC6: 12
A7: 1736 | B7: 12 | C7: 3.8333333 | D7: 20.916667 | E7: 0 | F7: 24.75 | G7: 40 | H7: 0.66591928 | I7: 0 | J7: 0 | K7: 0 | L7: 2.3333333 | M7: 2 | N7: 0 | O7: 5 | P7: 0 | Q7: 0 | R7: 22 | T7: 3 | U7: 1756 | V7: 163.33333 | W7: 19.166667 | X7: 144.16667 | Y7: 0 | Z7: 0 | AA7: 0.83333333 | AB7: 1 | AC7: 12
A8: 1756 | B8: 12 | C8: 19.166667 | D8: 144.16667 | E8: 0 | F8: 163.33333 | G8: 261 | H8: 0.83333333 | I8: 0 | J8: 0 | K8: 0 | L8: 4.3333333 | M8: 1 | N8: 1 | O8: 4 | P8: 12 | Q8: 0 | R8: 3 | T8: 4 | U8: 2040 | V8: 116.08333 | W8: 23.416667 | X8: 92.666667 | Y8: 0 | Z8: 0 | AA8: 0.78700565 | AB8: 1 | AC8: 12
A9: 2022 | B9: 12 | C9: 3.1666667 | D9: 35.666667 | E9: 0 | F9: 38.833333 | G9: 77 | H9: 0.85036496 | I9: 0 | J9: 0 | K9: 0 | L9: 3 | M9: 2 | N9: 1 | O9: 4 | P9: 2 | Q9: 0 | R9: 17 | T9: 5 | U9: 1625 | V9: 97 | W9: 26.416667 | X9: 70.583333 | Y9: 0 | Z9: 0 | AA9: 0.76679842 | AB9: 1 | AC9: 12
A10: 2039 | B10: 12 | C10: 1.1666667 | D10: 2.4166667 | E10: 1.6666667 | F10: 5.25 | G10: 15 | H10: 0.46236559 | I10: 0 | J10: 0.16666667 | K10: 0 | L10: 1.5 | M10: 12 | N10: 0 | O10: 5 | P10: 0 | Q10: 0 | R10: 31 | T10: 6 | U10: 8020 | V10: 92 | W10: 21.75 | X10: 70.25 | Y10: 0 | Z10: 0 | AA10: 0.84532925 | AB10: 4 | AC10: 12
A11: 2040 | B11: 12 | C11: 23.416667 | D11: 92.666667 | E11: 0 | F11: 116.08333 | G11: 149 | H11: 0.78700565 | I11: 0 | J11: 0 | K11: 0 | L11: 4.5 | M11: 0 | N11: 1 | O11: 1 | P11: 12 | Q11: 0 | R11: 4 | T11: 7 | U11: 2861 | V11: 83.083333 | W11: 16.25 | X11: 66.833333 | Y11: 0 | Z11: 0 | AA11: 0.86545139 | AB11: 2 | AC11: 12
A12: 2481 | B12: 12 | C12: 75.416667 | D12: 200.5 | E12: 0 | F12: 275.91667 | G12: 381 | H12: 0.79572218 | I12: 0 | J12: 0 | K12: 0 | L12: 4.75 | M12: 0 | N12: 1 | O12: 5 | P12: 12 | Q12: 0 | R12: 1 | T12: 8 | U12: 9082 | V12: 76.25 | W12: 8.1666667 | X12: 68.083333 | Y12: 0 | Z12: 0 | AA12: 0.93462717 | AB12: 1 | AC12: 12
A13: 2861 | B13: 12 | C13: 16.25 | D13: 66.833333 | E13: 0 | F13: 83.083333 | G13: 130 | H13: 0.86545139 | I13: 0 | J13: 0 | K13: 0 | L13: 4.6666667 | M13: 1 | N13: 2 | O13: 1 | P13: 12 | Q13: 0 | R13: 7 | T13: 9 | U13: 6237 | V13: 69.833333 | W13: 2.4166667 | X13: 67.416667 | Y13: 0 | Z13: 0 | AA13: 0.7570009 | AB13: 1 | AC13: 12
A14: 3067 | B14: 12 | C14: 3.0833333 | D14: 37.166667 | E14: 0 | F14: 40.25 | G14: 85 | H14: 0.86096257 | I14: 0 | J14: 0 | K14: 0 | L14: 3.75 | M14: 0 | N14: 2 | O14: 1 | P14: 2 | Q14: 0 | R14: 16 | T14: 10 | U14: 4096 | V14: 65.5 | W14: 9.0833333 | X14: 56.416667 | Y14: 0 | Z14: 0 | AA14: 0.85714286 | AB14: 2 | AC14: 2
A15: 3284 | B15: 12 | C15: 10.333333 | D15: 14.75 | E15: 0 | F15: 25.083333 | G15: 46 | H15: 0.66740576 | I15: 0 | J15: 0 | K15: 0 | L15: 1.9166667 | M15: 12 | N15: 0 | O15: 3 | P15: 0 | Q15: 0 | R15: 21 | T15: 11 | U15: 4655 | V15: 54.333333 | W15: 11.5 | X15: 42.833333 | Y15: 0 | Z15: 0 | AA15: 0.73589165 | AB15: 3 | AC15: 0
A16: 3488 | B16: 12 | C16: 0.41666667 | D16: 29.25 | E16: 0 | F16: 29.666667 | G16: 42 | H16: 0.6137931 | I16: 0 | J16: 0 | K16: 0 | L16: 2.5 | M16: 1 | N16: 0 | O16: 2 | P16: 0 | Q16: 0 | R16: 20 | T16: 12 | U16: 4423 | V16: 51.166667 | W16: 0.66666667 | X16: 45.5 | Y16: 5 | Z16: 0.5 | AA16: 0.78470255 | AB16: 3 | AC16: 3
A17: 4096 | B17: 12 | C17: 9.0833333 | D17: 56.416667 | E17: 0 | F17: 65.5 | G17: 117 | H17: 0.85714286 | I17: 0 | J17: 0 | K17: 0 | L17: 3.9166667 | M17: 0 | N17: 2 | O17: 1 | P17: 2 | Q17: 0 | R17: 10 | T17: 13 | U17: 8096 | V17: 48.333333 | W17: 12.5 | X17: 35.833333 | Y17: 0 | Z17: 0 | AA17: 0.6888361 | AB17: 2 | AC17: 1
... A35: 9082 | B35: 12 | C35: 8.1666667 | D35: 68.083333 | E35: 0 | F35: 76.25 | G35: 112 | H35: 0.93462717 | I35: 0 | J35: 0 | K35: 0 | L35: 4.3333333 | M35: 0 | N35: 1 | O35: 3 | P35: 12 | Q35: 0 | R35: 8 | T35: 31 | U35: 2039 | V35: 5.25 | W35: 1.1666667 | X35: 2.4166667 | Y35: 1.6666667 | Z35: 0.16666667 | AA35: 0.46236559 | AB35: 0 | AC35: 0

Sheet Team Lookup
A1: DERT #2040 - Team Lookup
A2: Type a team number in the yellow cell to see every scan of that team (including observations).
A3: Team #: | B3: 2040 | C3: =IF(B3="","",IFERROR(INDEX(_xlfn.ANCHORARRAY('Team Summary'!F5),MATCH(B3,_xlfn.ANCHORARRAY('Team Summary'!A5),0)),"")) -> 116.08333 | D3: =IF(B3="","",IFERROR("Rank "&INDEX(_xlfn.ANCHORARRAY('Team Summary'!R5),MATCH(B3,_xlfn.ANCHORARRAY('Team Summary'!A5),0))&" of "&ROWS(_xlfn.ANCHORARRAY('Team Summary'!A5)),"No scans yet")) -> Rank 4 of 31 | E3: {=IF(B3="","",IFERROR(_xlfn.XLOOKUP(B3,INDEX(_xlfn.ANCHORARRAY('TBA Teams'!$R$5),,1),INDEX(_xlfn.ANCHORARRAY('TBA Teams'!$R$5),,2),""),""))} -> DERT - Dunlap Eagles Robotics Team
A5: Schema | B5: Match type | C5: Match # | D5: Team # | E5: Alliance | F5: Station | G5: Scout name | H5: Robot on field? | I5: Starting position | J5: Fuel preloaded | K5: Auto fuel scored | L5: Auto fuel missed | M5: Auto path | N5: Picked up fuel from | O5: Tower climb in auto | P5: Teleop fuel scored | Q5: Teleop fuel missed | R5: Intake from | S5: Shoots from | T5: Drives over / through | U5: Inactive Hub behavior | V5: Fuel it can carry | W5: Played defense | X5: Was defended | Y5: Tower climb | Z5: Climb time | AA5: Driver skill | AB5: Robot speed | AC5: Shooting accuracy | AD5: Problems | AE5: Minor fouls | AF5: Major fouls | AG5: Card | AH5: Pick? | AI5: Observations | AJ5: Auto pts | AK5: Teleop fuel pts | AL5: Climb pts | AM5: Total pts | AN5: Submitted
A6: {=IF(B3="","",IFERROR(_xlfn.SORTBY(_xlfn._xlws.FILTER(Scans[],Scans[Team '#]=B3),_xlfn._xlws.FILTER(Scans[Match '#],Scans[Team '#]=B3),1),"No scans for this team yet"))} -> S39-44228b4d | B6: Qual | C6: 1 | D6: 2040 | E6: Blue | F6: 2 | G6: Ella | H6: Yes | I6: Left | J6: 5 | K6: 26 | L6: 8 | M6: Left start line; Went to Neutral Zone; Used Trench | N6: Neutral Zone | O6: None | P6: 61 | Q6: 18 | R6: Neutral Zone floor; Alliance Zone floor; Depot | S6: Close to Hub; Mid range; Long range; While moving | T6: Bump; Trench | U6: Collects / stockpiles; Passes fuel to our zone | V6: 40+ | W6: None | X6: No | Y6: None | Z6: 0 | AA6: 5 | AB6: 5 | AC6: 3 | AD6: 0 | AE6: 0 | AF6: 0 | AG6: None | AH6: Yes | AI6: Consistent cycles; shoots well from long range | AJ6: 26 | AK6: 61 | AL6: 0 | AM6: 87 | AN6: 3/20/2026, 9:04:04 AM
A7: S39-44228b4d | B7: Qual | C7: 7 | D7: 2040 | E7: Red | F7: 1 | G7: Ava | H7: Yes | I7: Left | J7: 5 | K7: 18 | L7: 4 | M7: Left start line; Went to Neutral Zone; Used Trench | N7: Neutral Zone | O7: None | P7: 127 | Q7: 25 | R7: Neutral Zone floor; Alliance Zone floor; Depot | S7: Close to Hub; Mid range; Long range; While moving | T7: Bump; Trench | U7: Collects / stockpiles; Passes fuel to our zone | V7: 40+ | W7: None | X7: No | Y7: None | Z7: 0 | AA7: 4 | AB7: 5 | AC7: 5 | AD7: 0 | AE7: 0 | AF7: 0 | AG7: None | AH7: Yes | AI7: High-volume scorer; shoots well from long range | AJ7: 18 | AK7: 127 | AL7: 0 | AM7: 145 | AN7: 3/20/2026, 9:51:28 AM
A8: S39-44228b4d | B8: Qual | C8: 12 | D8: 2040 | E8: Blue | F8: 1 | G8: Dev | H8: Yes | I8: Left | J8: 5 | K8: 27 | L8: 9 | M8: Left start line; Went to Neutral Zone; Used Trench | N8: Neutral Zone | O8: None | P8: 111 | Q8: 38 | R8: Neutral Zone floor; Alliance Zone floor; Depot | S8: Close to Hub; Mid range; Long range; While moving | T8: Bump; Trench | U8: Collects / stockpiles; Passes fuel to our zone | V8: 40+ | W8: None | X8: Some | Y8: None | Z8: 0 | AA8: 4 | AB8: 5 | AC8: 5 | AD8: 0 | AE8: 0 | AF8: 0 | AG8: None | AH8: Yes | AI8: High-volume scorer; shoots well from long range | AJ8: 27 | AK8: 111 | AL8: 0 | AM8: 138 | AN8: 3/20/2026, 10:32:17 AM
A9: S39-44228b4d | B9: Qual | C9: 18 | D9: 2040 | E9: Blue | F9: 2 | G9: Ella | H9: Yes | I9: Left | J9: 5 | K9: 35 | L9: 11 | M9: Left start line; Went to Neutral Zone; Used Trench | N9: Neutral Zone | O9: None | P9: 84 | Q9: 27 | R9: Neutral Zone floor; Alliance Zone floor; Depot | S9: Close to Hub; Mid range; Long range; While moving | T9: Bump; Trench | U9: Collects / stockpiles; Passes fuel to our zone | V9: 40+ | W9: None | X9: No | Y9: None | Z9: 0 | AA9: 4 | AB9: 4 | AC9: 3 | AD9: 0 | AE9: 0 | AF9: 0 | AG9: None | AH9: Yes | AI9: Consistent cycles | AJ9: 35 | AK9: 84 | AL9: 0 | AM9: 119 | AN9: 3/20/2026, 11:19:42 AM
A10: S39-44228b4d | B10: Qual | C10: 23 | D10: 2040 | E10: Blue | F10: 3 | G10: Finn | H10: Yes | I10: Left | J10: 5 | K10: 6 | L10: 1 | M10: Left start line; Went to Neutral Zone; Used Trench | N10: Neutral Zone | O10: None | P10: 51 | Q10: 8 | R10: Neutral Zone floor; Alliance Zone floor; Depot | S10: Close to Hub; Mid range; Long range; While moving | T10: Bump; Trench | U10: Collects / stockpiles; Passes fuel to our zone | V10: 40+ | W10: None | X10: Heavily | Y10: None | Z10: 0 | AA10: 4 | AB10: 5 | AC10: 5 | AD10: 0 | AE10: 0 | AF10: 0 | AG10: None | AH10: Yes | AI10: Consistent cycles | AJ10: 6 | AK10: 51 | AL10: 0 | AM10: 57 | AN10: 3/20/2026, 1:01:09 PM
A11: S39-44228b4d | B11: Qual | C11: 28 | D11: 2040 | E11: Blue | F11: 2 | G11: Ella | H11: Yes | I11: Left | J11: 5 | K11: 28 | L11: 7 | M11: Left start line; Went to Neutral Zone; Used Trench | N11: Neutral Zone | O11: None | P11: 118 | Q11: 30 | R11: Neutral Zone floor; Alliance Zone floor; Depot | S11: Close to Hub; Mid range; Long range; While moving | T11: Bump; Trench | U11: Collects / stockpiles; Passes fuel to our zone | V11: 40+ | W11: None | X11: Some | Y11: None | Z11: 0 | AA11: 5 | AB11: 4 | AC11: 5 | AD11: 0 | AE11: 0 | AF11: 0 | AG11: None | AH11: Yes | AI11: High-volume scorer | AJ11: 28 | AK11: 118 | AL11: 0 | AM11: 146 | AN11: 3/20/2026, 1:39:40 PM
A12: S39-44228b4d | B12: Qual | C12: 34 | D12: 2040 | E12: Red | F12: 1 | G12: Grace | H12: Yes | I12: Left | J12: 5 | K12: 20 | L12: 5 | M12: Left start line; Went to Neutral Zone; Crossed Bump | N12: Neutral Zone | O12: None | P12: 72 | Q12: 16 | R12: Neutral Zone floor; Alliance Zone floor; Depot | S12: Close to Hub; Mid range; Long range; While moving | T12: Bump; Trench | U12: Collects / stockpiles; Passes fuel to our zone | V12: 40+ | W12: None | X12: Some | Y12: None | Z12: 0 | AA12: 5 | AB12: 4 | AC12: 4 | AD12: 0 | AE12: 0 | AF12: 0 | AG12: None | AH12: Yes | AI12: Consistent cycles | AJ12: 20 | AK12: 72 | AL12: 0 | AM12: 92 | AN12: 3/20/2026, 2:27:37 PM
A13: S39-44228b4d | B13: Qual | C13: 37 | D13: 2040 | E13: Red | F13: 1 | G13: Grace | H13: Yes | I13: Left | J13: 5 | K13: 23 | L13: 7 | M13: Left start line; Went to Neutral Zone; Used Trench | N13: Depot | O13: None | P13: 126 | Q13: 38 | R13: Neutral Zone floor; Alliance Zone floor; Depot | S13: Close to Hub; Mid range; Long range; While moving | T13: Bump; Trench | U13: Collects / stockpiles; Passes fuel to our zone | V13: 40+ | W13: None | X13: Some | Y13: None | Z13: 0 | AA13: 4 | AB13: 5 | AC13: 4 | AD13: 0 | AE13: 0 | AF13: 0 | AG13: None | AH13: Yes | AI13: High-volume scorer; fed fuel to partners during inactive shift | AJ13: 23 | AK13: 126 | AL13: 0 | AM13: 149 | AN13: 3/20/2026, 2:51:55 PM
A14: S39-44228b4d | B14: Qual | C14: 44 | D14: 2040 | E14: Blue | F14: 3 | G14: Lily | H14: Yes | I14: Left | J14: 5 | K14: 19 | L14: 4 | M14: Left start line; Went to Neutral Zone; Used Trench | N14: Neutral Zone | O14: None | P14: 105 | Q14: 25 | R14: Neutral Zone floor; Alliance Zone floor; Depot | S14: Close to Hub; Mid range; Long range; While moving | T14: Bump; Trench | U14: Collects / stockpiles; Passes fuel to our zone | V14: 40+ | W14: None | X14: No | Y14: None | Z14: 0 | AA14: 5 | AB14: 4 | AC14: 4 | AD14: 0 | AE14: 0 | AF14: 0 | AG14: None | AH14: Yes | AI14: High-volume scorer; fed fuel to partners during inactive shift | AJ14: 19 | AK14: 105 | AL14: 0 | AM14: 124 | AN14: 3/21/2026, 9:28:41 AM
A15: S39-44228b4d | B15: Qual | C15: 49 | D15: 2040 | E15: Blue | F15: 2 | G15: Kai | H15: Yes | I15: Left | J15: 5 | K15: 29 | L15: 9 | M15: Left start line; Went to Neutral Zone; Crossed Bump | N15: Neutral Zone | O15: None | P15: 92 | Q15: 29 | R15: Neutral Zone floor; Alliance Zone floor; Depot | S15: Close to Hub; Mid range; Long range; While moving | T15: Bump; Trench | U15: Collects / stockpiles; Passes fuel to our zone | V15: 40+ | W15: None | X15: No | Y15: None | Z15: 0 | AA15: 5 | AB15: 5 | AC15: 3 | AD15: Fuel jam | AE15: 1 | AF15: 0 | AG15: None | AH15: Yes | AI15: High-volume scorer; shoots well from long range; fed fuel to partners during inactive shift | AJ15: 29 | AK15: 92 | AL15: 0 | AM15: 121 | AN15: 3/21/2026, 10:07:39 AM
A16: S39-44228b4d | B16: Qual | C16: 52 | D16: 2040 | E16: Red | F16: 3 | G16: Isla | H16: Yes | I16: Left | J16: 5 | K16: 23 | L16: 6 | M16: Left start line; Went to Neutral Zone; Used Trench | N16: Depot | O16: None | P16: 68 | Q16: 18 | R16: Neutral Zone floor; Alliance Zone floor; Depot | S16: Close to Hub; Mid range; Long range; While moving | T16: Bump; Trench | U16: Collects / stockpiles; Passes fuel to our zone | V16: 40+ | W16: None | X16: No | Y16: None | Z16: 0 | AA16: 5 | AB16: 5 | AC16: 4 | AD16: 0 | AE16: 0 | AF16: 0 | AG16: None | AH16: Yes | AI16: Consistent cycles | AJ16: 23 | AK16: 68 | AL16: 0 | AM16: 91 | AN16: 3/21/2026, 10:33:13 AM
A17: S39-44228b4d | B17: Qual | C17: 58 | D17: 2040 | E17: Red | F17: 3 | G17: Isla | H17: Yes | I17: Left | J17: 5 | K17: 27 | L17: 7 | M17: Left start line; Went to Neutral Zone; Used Trench | N17: Depot | O17: None | P17: 97 | Q17: 27 | R17: Neutral Zone floor; Alliance Zone floor; Depot | S17: Close to Hub; Mid range; Long range; While moving | T17: Bump; Trench | U17: Collects / stockpiles; Passes fuel to our zone | V17: 40+ | W17: None | X17: No | Y17: None | Z17: 0 | AA17: 4 | AB17: 5 | AC17: 4 | AD17: 0 | AE17: 0 | AF17: 0 | AG17: None | AH17: Yes | AI17: High-volume scorer | AJ17: 27 | AK17: 97 | AL17: 0 | AM17: 124 | AN17: 3/21/2026, 11:20:46 AM

Sheet Scouting Check
A1: DERT #2040 - Scouting Check
A2: Problems to fix in the Scans sheet. Updates by itself; paste TBA's team list and schedule (TBA Teams / TBA Schedule sheets) for the full check.
A4: Check | B4: Found | C4: What to do
A5: Scans | B5: =COUNTIF(Scans[Team '#],"<>") -> 372
A6: Duplicate scans (rows) | B6: =COUNTIF(INDEX(_xlfn.ANCHORARRAY($A$17),,1),"Duplicate scan") -> 0 | C6: Same match + team scanned more than once: delete the extra row on the Scans sheet.
A7: Matches without 6 scans | B7: =IF(COUNT(INDEX(_xlfn.ANCHORARRAY('TBA Schedule'!$R$5),,1))>0,"–",COUNTIF(INDEX(_xlfn.ANCHORARRAY($A$17),,1),"Not 6 scans")) -> – | C7: Find the missing scout, or a duplicate. (Replaced by the checks below once the schedule is pasted.)
A8: Robots not scouted | B8: =IF(COUNT(INDEX(_xlfn.ANCHORARRAY('TBA Schedule'!$R$5),,1))>0,COUNTIF(INDEX(_xlfn.ANCHORARRAY($A$17),,1),"Not scouted"),"needs schedule") -> 0 | C8: Ask that robot's scout to show the QR code again: Submitted matches in the app.
A9: Team not in that match | B9: =IF(COUNT(INDEX(_xlfn.ANCHORARRAY('TBA Schedule'!$R$5),,1))>0,COUNTIF(INDEX(_xlfn.ANCHORARRAY($A$17),,1),"Team not in that match"),"needs schedule") -> 0 | C9: Usually a typo in Team #: fix that cell on the Scans sheet.
A10: Team not at this event | B10: =IF(COUNT(INDEX(_xlfn.ANCHORARRAY('TBA Teams'!$R$5),,1))>0,IF(COUNT(INDEX(_xlfn.ANCHORARRAY('TBA Schedule'!$R$5),,1))>0,"–",COUNTIF(INDEX(_xlfn.ANCHORARRAY($A$17),,1),"Team not at this event")),"needs team list") -> – | C10: Usually a typo in Team #: fix that cell on the Scans sheet. (Checked per match instead once the schedule is pasted.)
A11: Wrong alliance | B11: =IF(COUNT(INDEX(_xlfn.ANCHORARRAY('TBA Schedule'!$R$5),,1))>0,COUNTIF(INDEX(_xlfn.ANCHORARRAY($A$17),,1),"Wrong alliance"),"needs schedule") -> 0 | C11: Fix the Alliance cell on the Scans sheet.
A12: TBA schedule | B12: =IF(COUNT(INDEX(_xlfn.ANCHORARRAY('TBA Schedule'!$R$5),,1))>0,COUNT(INDEX(_xlfn.ANCHORARRAY('TBA Schedule'!$R$5),,1))/6&" qual matches","not pasted yet") -> 62 qual matches | C12: See the TBA Schedule sheet.
A13: TBA team list | B13: =IF(COUNT(INDEX(_xlfn.ANCHORARRAY('TBA Teams'!$R$5),,1))>0,COUNT(INDEX(_xlfn.ANCHORARRAY('TBA Teams'!$R$5),,1))&" teams","not pasted yet") -> 31 teams | C13: See the TBA Teams sheet.
A15: PROBLEMS TO FIX
A16: Problem | B16: Match # | C16: Team # | D16: Alliance | E16: Excel row | F16: Scout | G16: What it means
A17: {=_xlfn.LET(_xlpm.ty,Scans[Match type],_xlpm.mt,Scans[Match '#],_xlpm.tm,Scans[Team '#],_xlpm.al,Scans[Alliance],_xlpm.sc,Scans[Scout name],_xlpm.rw,ROW(Scans[Team '#]),_xlpm.nT,_xlfn.SEQUENCE(ROWS(_xlpm.tm)),_xlpm.has,_xlpm.tm<>"",_xlpm.qual,_xlpm.has*((_xlpm.ty="Qual")+(_xlpm.ty="")),_xlpm.s,_xlfn.ANCHORARRAY('TBA Schedule'!$R$5),_xlpm.sm,INDEX(_xlpm.s,,1),_xlpm.sa,INDEX(_xlpm.s,,2),_xlpm.st,INDEX(_xlpm.s,,3),_xlpm.nS,_xlfn.SEQUENCE(ROWS(_xlpm.sm)),_xlpm.hasSched,COUNT(_xlpm.sm)>0,_xlpm.dupN,COUNTIFS(Scans[Team '#],_xlpm.tm,Scans[Match '#],_xlpm.mt,Scans[Match type],_xlpm.ty),_xlpm.dup,_xlfn._xlws.FILTER(_xlfn.HSTACK(IF(_xlpm.nT,"Duplicate scan"),_xlpm.mt,_xlpm.tm,_xlpm.al,_xlpm.rw,_xlpm.sc,"Scanned "&_xlpm.dupN&" times: delete the extra row"),_xlpm.has*(_xlpm.dupN>1),""),_xlpm.qm,_xlfn.UNIQUE(_xlfn._xlws.FILTER(_xlpm.mt,_xlpm.qual,"")),_xlpm.nQ,_xlfn.SEQUENCE(ROWS(_xlpm.qm)),_xlpm.qc,COUNTIFS(Scans[Match '#],_xlpm.qm,Scans[Team '#],"<>",Scans[Match type],"Qual")+COUNTIFS(Scans[Match '#],_xlpm.qm,Scans[Team '#],"<>",Scans[Match type],""),_xlpm.cnt,IF(_xlpm.hasSched,"",_xlfn._xlws.FILTER(_xlfn.HSTACK(IF(_xlpm.nQ,"Not 6 scans"),_xlpm.qm,IF(_xlpm.nQ,""),IF(_xlpm.nQ,""),IF(_xlpm.nQ,""),IF(_xlpm.nQ,""),_xlpm.qc&" scans in this match, expected 6"),(_xlpm.qm<>"")*(_xlpm.qc<>6),"")),_xlpm.last,MAX(_xlfn._xlws.FILTER(_xlpm.mt,_xlpm.qual,0)),_xlpm.seen,COUNTIFS(Scans[Match '#],_xlpm.sm,Scans[Team '#],_xlpm.st,Scans[Match type],"Qual")+COUNTIFS(Scans[Match '#],_xlpm.sm,Scans[Team '#],_xlpm.st,Scans[Match type],""),_xlpm.miss,IF(_xlpm.hasSched,_xlfn._xlws.FILTER(_xlfn.HSTACK(IF(_xlpm.nS,"Not scouted"),_xlpm.sm,_xlpm.st,_xlpm.sa,IF(_xlpm.nS,""),IF(_xlpm.nS,""),IF(_xlpm.nS,"Nobody scanned this robot: ask its scout to show the QR code again (Submitted matches)")),ISNUMBER(_xlpm.sm)*(_xlpm.sm<=_xlpm.last)*(_xlpm.seen=0),""),""),_xlpm.inM,COUNTIFS(_xlpm.sm,_xlpm.mt,_xlpm.st,_xlpm.tm),_xlpm.wt,IF(_xlpm.hasSched,_xlfn._xlws.FILTER(_xlfn.HSTACK(IF(_xlpm.nT,"Team not in that match"),_xlpm.mt,_xlpm.tm,_xlpm.al,_xlpm.rw,_xlpm.sc,IF(COUNTIFS(_xlpm.sm,_xlpm.mt)>0,"Typo in Team #? Check the schedule for this match","There is no such qual match on the TBA schedule")),_xlpm.qual*(_xlpm.inM=0),""),""),_xlpm.inA,COUNTIFS(_xlpm.sm,_xlpm.mt,_xlpm.st,_xlpm.tm,_xlpm.sa,_xlpm.al),_xlpm.wa,IF(_xlpm.hasSched,_xlfn._xlws.FILTER(_xlfn.HSTACK(IF(_xlpm.nT,"Wrong alliance"),_xlpm.mt,_xlpm.tm,_xlpm.al,_xlpm.rw,_xlpm.sc,"The schedule says "&_xlfn.XLOOKUP(_xlpm.mt&"|"&_xlpm.tm,_xlpm.sm&"|"&_xlpm.st,_xlpm.sa,"?")),_xlpm.qual*(_xlpm.inM>0)*(_xlpm.inA=0),""),""),_xlpm.tl,_xlfn.ANCHORARRAY('TBA Teams'!$R$5),_xlpm.tn,INDEX(_xlpm.tl,,1),_xlpm.hasTeams,COUNT(_xlpm.tn)>0,_xlpm.ne,IF(_xlpm.hasTeams*NOT(_xlpm.hasSched),_xlfn._xlws.FILTER(_xlfn.HSTACK(IF(_xlpm.nT,"Team not at this event"),_xlpm.mt,_xlpm.tm,_xlpm.al,_xlpm.rw,_xlpm.sc,IF(_xlpm.nT,"Not on TBA's team list for this event: typo in Team #?")),_xlpm.has*(COUNTIFS(_xlpm.tn,_xlpm.tm)=0),""),""),_xlpm.all,_xlfn.VSTACK(_xlpm.dup,_xlpm.cnt,_xlpm.miss,_xlpm.wt,_xlpm.ne,_xlpm.wa),_xlfn._xlws.FILTER(_xlpm.all,IFERROR(INDEX(_xlpm.all,,1)<>"",FALSE),"✓ Nothing to fix"))} -> ✓ Nothing to fix

Sheet TBA Schedule
A1: DERT #2040 - TBA Schedule
A2: Paste TBA's Flat Schedule here so the Scouting Check can find unscouted robots, team-number typos and wrong alliances.
R3: Read from the paste (don't type here)
A4: Paste the Flat Schedule here: click the yellow cell, then press Ctrl+V | J4: HOW TO GET THE SCHEDULE | R4: Match # | S4: Alliance | T4: Team #
A5: match_key,scheduled_date,scheduled_time,comp_level,match_number,set_number,color,team | J5: 1. On thebluealliance.com open your event (for example thebluealliance.com/event/2026iltrr) and click the Scouting tab. | R5: {=_xlfn.LET(_xlpm.src,A1:H2000,_xlpm.a,INDEX(_xlpm.src,,1),_xlpm.line,IF(INDEX(_xlpm.src,,2)="",_xlpm.a,_xlpm.a&","&INDEX(_xlpm.src,,2)&","&INDEX(_xlpm.src,,3)&","&INDEX(_xlpm.src,,4)&","&INDEX(_xlpm.src,,5)&","&INDEX(_xlpm.src,,6)&","&INDEX(_xlpm.src,,7)&","&INDEX(_xlpm.src,,8)),_xlpm.t,","&_xlpm.line&",",_xlpm.lvl,IFERROR(_xlfn.TEXTBEFORE(_xlfn.TEXTAFTER(_xlpm.t,",",4),","),""),_xlpm.num,IFERROR(--_xlfn.TEXTBEFORE(_xlfn.TEXTAFTER(_xlpm.t,",",5),","),""),_xlpm.side,LOWER(IFERROR(_xlfn.TEXTBEFORE(_xlfn.TEXTAFTER(_xlpm.t,",",7),","),"")),_xlpm.tm,IFERROR(--_xlfn.TEXTBEFORE(_xlfn.TEXTAFTER(_xlpm.t,",",8),","),""),_xlpm.keep,ISNUMBER(_xlpm.num)*ISNUMBER(_xlpm.tm)*(_xlpm.lvl="qm")*((_xlpm.side="red")+(_xlpm.side="blue")),IFERROR(_xlfn._xlws.FILTER(_xlfn.HSTACK(_xlpm.num,PROPER(_xlpm.side),_xlpm.tm),_xlpm.keep),_xlfn.HSTACK("","","")))} -> 1 | S5: Red | T5: 2039
A6: 2026ilpe_qm1,2026-03-20,08:50 AM,qm,1,1,red,2039 | J6: 2. Under Flat Schedule, click Copy to Clipboard. | R6: 1 | S6: Red | T6: 6237
A7: 2026ilpe_qm1,2026-03-20,08:50 AM,qm,1,1,red,6237 | J7: 3. Click the yellow cell A5 on this sheet and press Ctrl+V. | R7: 1 | S7: Red | T7: 4645
A8: 2026ilpe_qm1,2026-03-20,08:50 AM,qm,1,1,red,4645 | J8: 4. Done: the Scouting Check sheet now compares every scan with the schedule. | R8: 1 | S8: Blue | T8: 2022
A9: 2026ilpe_qm1,2026-03-20,08:50 AM,qm,1,1,blue,2022 | J9: Paste again (over the old one) if the schedule changes. TBA usually has it the day before quals. | R9: 1 | S9: Blue | T9: 2040
A10: 2026ilpe_qm1,2026-03-20,08:50 AM,qm,1,1,blue,2040 | J10: To remove it: select columns A to H from row 5 down and press Delete. | R10: 1 | S10: Blue | T10: 9082
A11: 2026ilpe_qm1,2026-03-20,08:50 AM,qm,1,1,blue,9082 | R11: 2 | S11: Red | T11: 3284
A12: 2026ilpe_qm2,2026-03-20,09:00 AM,qm,2,1,red,3284 | R12: 2 | S12: Red | T12: 1756
A13: 2026ilpe_qm2,2026-03-20,09:00 AM,qm,2,1,red,1756 | R13: 2 | S13: Red | T13: 4655
A14: 2026ilpe_qm2,2026-03-20,09:00 AM,qm,2,1,red,4655 | R14: 2 | S14: Blue | T14: 3067
A15: 2026ilpe_qm2,2026-03-20,09:00 AM,qm,2,1,blue,3067 | R15: 2 | S15: Blue | T15: 4143
A16: 2026ilpe_qm2,2026-03-20,09:00 AM,qm,2,1,blue,4143 | R16: 2 | S16: Blue | T16: 7848
A17: 2026ilpe_qm2,2026-03-20,09:00 AM,qm,2,1,blue,7848 | R17: 3 | S17: Red | T17: 7417
A18: 2026ilpe_qm3,2026-03-20,09:10 AM,qm,3,1,red,7417 | R18: 3 | S18: Red | T18: 4787
A19: 2026ilpe_qm3,2026-03-20,09:10 AM,qm,3,1,red,4787 | R19: 3 | S19: Red | T19: 4213
A20: 2026ilpe_qm3,2026-03-20,09:10 AM,qm,3,1,red,4213 | R20: 3 | S20: Blue | T20: 1736
A21: 2026ilpe_qm3,2026-03-20,09:10 AM,qm,3,1,blue,1736 | R21: 3 | S21: Blue | T21: 5442
A22: 2026ilpe_qm3,2026-03-20,09:10 AM,qm,3,1,blue,5442 | R22: 3 | S22: Blue | T22: 8719
... A376: 2026ilpe_qm62,2026-03-21,11:30 AM,qm,62,1,blue,1625 | R376: 62 | S376: Blue | T376: 648
A377: 2026ilpe_qm62,2026-03-21,11:30 AM,qm,62,1,blue,648
A378: 2026ilpe_sf1m1,2026-03-21,01:30 PM,sf,1,1,red,2481
A379: 2026ilpe_sf1m1,2026-03-21,01:30 PM,sf,1,1,red,7417
A380: 2026ilpe_sf1m1,2026-03-21,01:30 PM,sf,1,1,red,1756
A381: 2026ilpe_sf1m1,2026-03-21,01:30 PM,sf,1,1,blue,3284
A382: 2026ilpe_sf1m1,2026-03-21,01:30 PM,sf,1,1,blue,6237
A383: 2026ilpe_sf1m1,2026-03-21,01:30 PM,sf,1,1,blue,5442
A384: 2026ilpe_sf2m1,2026-03-21,01:39 PM,sf,1,2,red,1736
A385: 2026ilpe_sf2m1,2026-03-21,01:39 PM,sf,1,2,red,1625
A386: 2026ilpe_sf2m1,2026-03-21,01:39 PM,sf,1,2,red,4096
A387: 2026ilpe_sf2m1,2026-03-21,01:39 PM,sf,1,2,blue,3067
A388: 2026ilpe_sf2m1,2026-03-21,01:39 PM,sf,1,2,blue,8029
... A473: 2026ilpe_f1m3,2026-03-21,04:36 PM,f,3,1,blue,1756

Sheet TBA Teams
A1: DERT #2040 - TBA Teams
A2: Paste TBA's Team List here so the Scouting Check can spot team numbers that aren't at this event, and Team Lookup can show names.
R3: Read from the paste (don't type here)
A4: Paste the Team List here: click the yellow cell, then press Ctrl+V | J4: HOW TO GET THE TEAM LIST | R4: Team # | S4: Name
A5: team_number,team_name,city,state_prov,country,robot_image_url | J5: 1. On thebluealliance.com open your event (for example thebluealliance.com/event/2026iltrr) and click the Scouting tab. | R5: {=_xlfn.LET(_xlpm.src,A1:F1000,_xlpm.a,INDEX(_xlpm.src,,1),_xlpm.b,INDEX(_xlpm.src,,2),_xlpm.split,_xlpm.b<>"",_xlpm.num,IFERROR(--IF(_xlpm.split,_xlpm.a,_xlfn.TEXTBEFORE(_xlpm.a&",",",")),""),_xlpm.rest,IFERROR(_xlfn.TEXTAFTER(_xlpm.a,","),""),_xlpm.name,IF(_xlpm.split,_xlpm.b,IF(LEFT(_xlpm.rest,1)="""",IFERROR(_xlfn.TEXTBEFORE(MID(_xlpm.rest,2,500),""""),""),IFERROR(_xlfn.TEXTBEFORE(_xlpm.rest&",",","),""))),IFERROR(_xlfn._xlws.FILTER(_xlfn.HSTACK(_xlpm.num,_xlpm.name),ISNUMBER(_xlpm.num)),_xlfn.HSTACK("","")))} -> 648 | S5: QC ELITE Flaming Squirrels
A6: 648,QC ELITE Flaming Squirrels,Moline,Illinois,USA,https://i.imgur.com/wSZuD0wm.jpg | J6: 2. Under Team List, click Copy to Clipboard. | R6: 1625 | S6: Winnovation
A7: 1625,Winnovation,Winnebago,Illinois,USA, | J7: 3. Click the yellow cell A5 on this sheet and press Ctrl+V. | R7: 1736 | S7: Robot Casserole
A8: 1736,Robot Casserole,Peoria,Illinois,USA,https://i.imgur.com/N1FgZ0nm.jpg | J8: TBA usually has the team list a week or two before the event. Paste again (over the old one) if teams are added. | R8: 1756 | S8: Argos
A9: 1756,Argos,Peoria,Illinois,USA,https://i.imgur.com/WgUNKahm.jpg | J9: To remove it: select columns A to F from row 5 down and press Delete. | R9: 2022 | S9: Titan Robotics
A10: 2022,Titan Robotics,Aurora,Illinois,USA,https://i.imgur.com/eMPUR2Bm.jpg | R10: 2039 | S10: Rockford Robotics
A11: 2039,Rockford Robotics,Rockford,Illinois,USA, | R11: 2040 | S11: DERT - Dunlap Eagles Robotics Team
A12: 2040,DERT - Dunlap Eagles Robotics Team,Dunlap,Illinois,USA,https://i.imgur.com/VLKYCJEm.jpg | R12: 2481 | S12: Roboteers
A13: 2481,Roboteers,Tremont,Illinois,USA,https://i.imgur.com/5ZOkuvbm.jpg | R13: 2861 | S13: Infinity's End
A14: 2861,Infinity's End,Lake City,Minnesota,USA, | R14: 3067 | S14: Robovikes
A15: 3067,Robovikes,Geneva,Illinois,USA, | R15: 3284 | S15: Camdenton LASER 3284
A16: 3284,Camdenton LASER 3284,Camdenton,Missouri,USA, | R16: 3488 | S16: Eagle Army 3488
A17: 3488,Eagle Army 3488,Orland Park,Illinois,USA, | R17: 4096 | S17: Ctrl-Z
A18: 4096,Ctrl-Z,Champaign,Illinois,USA,https://i.imgur.com/TJWGnOAm.jpg | R18: 4143 | S18: MARS/WARS
A19: 4143,MARS/WARS,Metamora,Illinois,USA,https://i.imgur.com/bieeiS4m.jpg | R19: 4156 | S19: Ninjaneers
A20: 4156,Ninjaneers,Springfield,Illinois,USA, | R20: 4213 | S20: MetalCow Robotics
A21: 4213,MetalCow Robotics,Bloomington,Illinois,USA, | R21: 4423 | S21: MARS' Minions
... A35: 8719,Oakville Dynamics,Saint Louis,Missouri,USA, | R35: 9082 | S35: No Limit
A36: 9082,No Limit,Pleasant Valley,Iowa,USA,
